Workbook

Sheet Resumo
A1: Auditoria de estilos e cores — Painel Trabalho Extra vs statusOPT
A2: Objetivo: aproximar ao máximo o painel_trabalho_extra.html da linguagem visual do statusOPT.html (referência). Análise feita sobre os dois ficheiros enviados.
A3: Ficheiros: painel_trabalho_extra.html (4257 linhas) · statusOPT.html (9101 linhas, versão enviada). As colunas "Prioridade" e "Estado" de cada folha têm listas para ir acompanhando; as contagens abaixo atualizam sozinhas.
A5: Contagem por folha
A6: Folha | B6: Itens | C6: Alta | D6: Média | E6: Baixa | F6: Feitos
A7: KPIs Painel TE | B7: =COUNTA('KPIs Painel TE'!A5:A22) -> 18 | C7: =COUNTIF('KPIs Painel TE'!P5:P22,"Alta") -> 7 | D7: =COUNTIF('KPIs Painel TE'!P5:P22,"Média") -> 10 | E7: =COUNTIF('KPIs Painel TE'!P5:P22,"Baixa") -> 1 | F7: =COUNTIF('KPIs Painel TE'!R5:R22,"Feito") -> 0
A8: Cores Painel TE | B8: =COUNTA('Cores Painel TE'!A5:A46) -> 42 | C8: =COUNTIF('Cores Painel TE'!H5:H46,"Alta") -> 18 | D8: =COUNTIF('Cores Painel TE'!H5:H46,"Média") -> 17 | E8: =COUNTIF('Cores Painel TE'!H5:H46,"Baixa") -> 7 | F8: =COUNTIF('Cores Painel TE'!I5:I46,"Feito") -> 0
A9: Gráficos | B9: =COUNTA(Gráficos!A5:A15) -> 11 | C9: =COUNTIF(Gráficos!L5:L15,"Alta") -> 4 | D9: =COUNTIF(Gráficos!L5:L15,"Média") -> 7 | E9: =COUNTIF(Gráficos!L5:L15,"Baixa") -> 0 | F9: =COUNTIF(Gráficos!M5:M15,"Feito") -> 0
A10: Componentes | B10: =COUNTA(Componentes!A5:A25) -> 21 | C10: =COUNTIF(Componentes!G5:G25,"Alta") -> 6 | D10: =COUNTIF(Componentes!G5:G25,"Média") -> 9 | E10: =COUNTIF(Componentes!G5:G25,"Baixa") -> 6 | F10: =COUNTIF(Componentes!I5:I25,"Feito") -> 0
A11: Plano de Ação | B11: =COUNTA('Plano de Ação'!A5:A19) -> 15 | C11: =COUNTIF('Plano de Ação'!E5:E19,"Alta") -> 10 | D11: =COUNTIF('Plano de Ação'!E5:E19,"Média") -> 4 | E11: =COUNTIF('Plano de Ação'!E5:E19,"Baixa") -> 1 | F11: =COUNTIF('Plano de Ação'!G5:G19,"Feito") -> 0
A12: Total | B12: =SUM(B7:B11) -> 107 | C12: =SUM(C7:C11) -> 45 | D12: =SUM(D7:D11) -> 47 | E12: =SUM(E7:E11) -> 15 | F12: =SUM(F7:F11) -> 0
A13: Progresso | B13: =IF(B12=0,0,F12/B12) -> 0
A15: Principais conclusões
A16: 1. Filosofia de cor oposta: o painel pinta o cartão inteiro (fundo + barra lateral) e deixa o número preto; o statusOPT deixa o cartão neutro e pinta só o número. É a mudança com mais impacto visual.
A17: 2. O painel não tem variáveis de tema nem tema escuro: ~40 cores escritas à mão em CSS, HTML inline e JS. O statusOPT concentra tudo em ~27 variáveis e troca de tema num clique.
A18: 3. Cores sem significado de estado: barras laterais azul/verde/amarelo/laranja nos cartões de contagem (Peças, Operadores, Turnos por categoria) competem com o semáforo. No statusOPT só há cor onde há juízo (bom/atenção/mau).
A19: 4. Limiares diferentes para o mesmo conceito: Produzido/Planeado no painel fica verde até 101% e amarelo acima; no statusOPT é verde até 110% e vermelho acima. Propõe-se R1 (statusOPT) para Adesão e Cobertura.
A20: 5. Gráficos sem leitura do tema: eixos, grelha e rótulos usam as cores por defeito do Chart.js e #1e293b — ficam invisíveis num fundo escuro. O statusOPT usa corTema().
A21: 6. Tipografia dispersa: 6 tamanhos de título de KPI (0.6–0.85rem) e 5 de valor (1.5–2.8rem), quase todos inline. O statusOPT usa 3 classes.
A22: 7. O próprio statusOPT tem 2 inconsistências a rever (folha Regras de Cor, N2 e N3) e contraste fraco das cores de semáforo no tema claro (N1).
A24: Decisões que preciso de ti
A25: D1. Δ Turnos: limiar entre atraso leve (laranja) e grave (vermelho) — sugestão −3 turnos. E o excesso (Δ > 0) fica verde como no statusOPT, ou ciano para se distinguir do "igual"?
A26: D2. Cartões de gráfico: retirar a borda superior colorida (o statusOPT não tem) ou mantê-la como código Área/C.C.?
A27: D3. Tema por defeito no painel: escuro (igual ao statusOPT) ou claro?
A29: Folhas
A30: Tokens statusOPT | B30: Variáveis de tema (escuro/claro) com amostras e cores fixas com contraste.
A31: Cores Painel TE | B31: Todas as cores do painel, quantas vezes aparecem e por qual substituir.
A32: KPIs Painel TE | B32: Os 18 indicadores do painel, estilo atual vs padrão a aplicar.
A33: Ref. statusOPT | B33: Como cada indicador do statusOPT é pintado (referência).
A34: Regras de Cor | B34: Limiares de semáforo de ambos e as regras propostas R1–R3.
A35: Gráficos | B35: Os 11 gráficos do painel: séries, eixos, rótulos.
A36: Componentes | B36: Cabeçalho, filtros, acordeão, cartões, tabelas, botões…
A37: Tipografia | B37: Escala de tamanhos e pesos.
A38: Plano de Ação | B38: Ordem de implementação em 6 fases.

Sheet Tokens statusOPT
A1: Paleta de referência — variáveis de tema do statusOPT
A2: Copiar este bloco :root (escuro, por defeito) e :root[data-theme=light] para o painel é o primeiro passo: todo o resto passa a usar var(--…). As amostras rgba estão misturadas sobre o fundo do respetivo tema.
A4: Variável CSS | B4: Tema escuro (defeito) | C4: Amostra escuro | D4: Tema claro | E4: Amostra claro | F4: Para que serve | G4: Substitui no painel
A5: --sp-primary | B5: #06b6d4 | D5: #06b6d4 (igual) | F5: Cor primária da marca (ciano) | G5: --sp-primary #005a9e
A6: --sp-bg | B6: #0f172a | D6: #eef2f7 | F6: Fundo da página | G6: --sp-bg #f4f6f9, html/body
A7: --card-shadow | B7: 0 8px 24px rgba(0, 0, 0, 0.4) | D7: 0 2px 8px rgba(15, 23, 42, 0.12) | F7: Sombra dos cartões | G7: --card-shadow 0 4px 12px rgba(0,0,0,.06)
A8: --bg-card | B8: #1e293b | D8: #ffffff | F8: Fundo de cartões, secções, tabelas | G8: background: white / #fff em todos os cartões
A9: --bg-subtle | B9: #090d16 | D9: #e2e8f0 | F9: Fundo de destaque discreto (ex.: desvio do CC) | G9: accordion-body #f8fafc
A10: --bg-inset | B10: #0f172a | D10: #f1f5f9 | F10: Superfícies encaixadas: campos, cabeçalhos de tabela | G10: table-dark #212529, inputs #fff
A11: --bg-elevated | B11: #1e293b | D11: #ffffff | F11: Painéis flutuantes: dropdowns, filtros de coluna | G11: dropdown-menu (Bootstrap branco)
A12: --bg-future-row | B12: rgba(15, 23, 42, 0.8) | D12: rgba(226, 232, 240, 0.75) | F12: Linhas de datas futuras | G12: —
A13: --bg-stripe | B13: #162032 | D13: #f1f5f9 | F13: Risca das linhas alternadas | G13: table-striped (Bootstrap)
A14: --border-color | B14: #334155 | D14: #cbd5e1 | F14: Todas as bordas | G14: #e2e8f0, #ced4da, #dee2e6, #cbd5e1
A15: --teal-accent | B15: #14b8a6 | D15: #0f766e | F15: Acento secundário | G15: —
A16: --cyan-accent | B16: #22d3ee | D16: #0e7490 | F16: Acento principal: títulos, botões, filtros ativos | G16: #005a9e (títulos, acordeão), #0d6efd (Bootstrap)
... A31: --btn-danger | B31: #f87171 | D31: #b91c1c | F31: Botões perigo | G31: #dc3545
A33: Cores fixas do statusOPT (não mudam com o tema)
A34: Cor | B34: Hex | C34: Amostra | D34: Contraste s/ cartão escuro | E34: Contraste s/ branco | F34: Significado / onde | G34: Nota
A35: Verde OK | B35: #34d399 | D35: 7.61 | E35: 1.92 | F35: Valor dentro do objetivo, avanço, 0 erros; ponto "Qtd. Produzida"; série Produzida
A36: Laranja alerta | B36: #fb923c | D36: 6.46 | E36: 2.26 | F36: Zona de atenção (80–90%), atraso < 8h, backlog, dados a envelhecer
A37: Laranja % CC > 8h | B37: #fd7e14 | D37: 5.69 | E37: 2.57 | F37: Banda intermédia só do cartão % CC em atraso > 8H | G37: Inconsistência interna: os outros alertas usam #fb923c
A38: Vermelho crítico | B38: #f87171 | D38: 5.29 | E38: 2.77 | F38: Fora do objetivo, atraso ≥ 8h, dados muito velhos
A39: Azul "planeado" | B39: #38bdf8 | D39: 6.83 | E39: 2.14 | F39: Ponto da Qtd. Planeada no cartão duplo
A40: Ciano gráficos | B40: #22d3ee | D40: 8.09 | E40: 1.81 | F40: Barras por Área, série Planeada, Adiantado
A41: Violeta | B41: #a78bfa | D41: 5.38 | E41: 2.72 | F41: Barras Nº de produções
A42: Azul ensaio | B42: #8bb3f2 | D42: 6.85 | E42: 2.14 | F42: Etiqueta/ícone de ensaio
A43: Vermelho risco | B43: #ef4444 | D43: 3.89 | E43: 3.76 | F43: Borda do módulo Material em risco; Previsão TE > 0
A44: Verde previsão | B44: #22c55e | D44: 6.42 | E44: 2.28 | F44: Previsão TE = 0
A45: MOD verde | B45: #059669 | D45: 3.88 | E45: 3.77 | F45: Célula MOD OK
A46: MOD laranja | B46: #d97706 | D46: 4.59 | E46: 3.19 | F46: Célula MOD com falta
A48: Contraste: razão WCAG 2.1 calculada a partir dos hex (texto normal precisa de ≥ 4,5:1; texto grande/negrito ≥ 3:1). Os verdes/laranjas fixos ficam abaixo de 3:1 sobre branco — ver folha "Regras de Cor", nota N1.

Sheet Cores Painel TE
A1: Inventário de todas as cores escritas à mão no painel_trabalho_extra
A2: Contagem automática no ficheiro (CSS + HTML + JS). Cada cor tem o equivalente statusOPT que a deve substituir.
A4: Cor no painel | B4: Amostra atual | C4: Ocorrências | D4: Onde é usada / significado | E4: Substituir por (statusOPT) | F4: Amostra escuro | G4: Amostra claro | H4: Prioridade | I4: Estado
A5: #005a9e | C5: 9 | D5: Primária: barra do cabeçalho, acordeão, títulos ativos, barras por Área, linhas dos gráficos, borda Peças Planeadas | E5: var(--cyan-accent) | F5: #22d3ee | G5: #0e7490 | H5: Alta | I5: Por fazer
A6: #10b981 | C6: 4 | D6: Cor do C.C.: barras por C.C., borda Peças Produzidas, --sp-success | E6: #34d399 (verde OK / série C.C.) | F6: #34d399 | G6: #34d399 | H6: Alta | I6: Por fazer
A7: #f4f6f9 | C7: 1 | D7: Fundo da página (--sp-bg) | E7: var(--sp-bg) | F7: #0f172a | G7: #eef2f7 | H7: Alta | I7: Por fazer
A8: #ffffff | C8: 21 | D8: Fundo de cabeçalho, cartões, gráficos, tabelas, dropdowns (white / #fff) | E8: var(--bg-card) | F8: #1e293b | G8: #ffffff | H8: Alta | I8: Por fazer
A9: #333 | C9: 2 | D9: Texto do body | E9: var(--text-main) | F9: #f8fafc | G9: #0f172a | H9: Alta | I9: Por fazer
A10: #1e293b | C10: 12 | D10: Texto do cabeçalho e acordeão; rótulos de dados dos gráficos | E10: var(--text-strong) / var(--chart-text-strong) | F10: #e2e8f0 | G10: #0f172a | H10: Alta | I10: Por fazer
A11: #64748b | C11: 13 | D11: Títulos de KPI (.kpi-title), neutro dos gráficos e botões Semana/Mês | E11: var(--text-muted) | F11: #94a3b8 | G11: #64748b | H11: Média | I11: Por fazer
A12: #475569 | C12: 1 | D12: Texto das etiquetas de secção (.section-tag) | E12: var(--text-label) | F12: #cbd5e1 | G12: #334155 | H12: Média | I12: Por fazer
A13: #e2e8f0 | C13: 4 | D13: Bordas do cabeçalho; fundo das etiquetas de secção | E13: var(--border-color) | F13: #334155 | G13: #cbd5e1 | H13: Média | I13: Por fazer
A14: #cbd5e1 | C14: 1 | D14: Borda superior dos cartões de gráfico | E14: var(--border-color) | F14: #334155 | G14: #cbd5e1 | H14: Baixa | I14: Por fazer
A15: #ced4da | C15: 2 | D15: Bordas dos filtros multiselect | E15: var(--border-color) | F15: #334155 | G15: #cbd5e1 | H15: Média | I15: Por fazer
A16: #eef5fc | C16: 1 | D16: Botão do acordeão aberto | E16: var(--bg-card) | F16: #1e293b | G16: #ffffff | H16: Média | I16: Por fazer
... A45: rgba(220, 53, 69, 0.1) | C45: 1 | D45: Preenchimento da linha % Cobertura | E45: rgba(34,211,238,0.15) | F45: rgba .15 | G45: rgba .15 | H45: Média | I45: Por fazer
A46: rgba(0, 0, 0, 0.06) | C46: 1 | D46: Sombra dos cartões | E46: var(--card-shadow) | H46: Média | I46: Por fazer

Sheet KPIs Painel TE
A1: Cada indicador do painel: estilo atual → padrão statusOPT a aplicar
A2: Princípio do statusOPT: o cartão é sempre neutro (fundo do cartão + borda fina); a cor do semáforo vai SÓ no número. O painel faz o contrário (pinta fundo e barra lateral).
A4: ID | B4: Secção | C4: Indicador | D4: Elemento (id) | E4: Cartão atual | F4: Fundo atual | G4: Barra lateral atual | H4: Cor do valor atual | I4: Tamanho título / valor (atual) | J4: Regra de cor atual | K4: Equivalente no statusOPT | L4: Padrão statusOPT a aplicar | M4: Regra a aplicar | N4: Cor valor (escuro) | O4: Recomendação | P4: Prioridade | Q4: Esforço | R4: Estado
A5: K01 | B5: Métricas | C5: PRODUZIDO/PLANEADO (%) | D5: kpiAdesaoPct / kpiAdesaoCard | E5: .kpi-card.highlight-card | F5: #d1e7dd | G5: 8px #198754 | H5: text-dark (fixo) | I5: 0.8rem / 2.8rem | J5: > 101% amarelo · ≥ 90% verde · ≥ 80% amarelo · < 80% vermelho (pinta fundo + barra; o número fica preto) | K5: Qtd. PRODUZIDO/PLANEADO (%) — cartão 4 do Dashboard; PRODUZIDO/PLANEADO no Histórico | L5: .opt-summary-card.opt-summary-card-main (borda ciano + brilho; título ciano; valor 2.1rem 800) | M5: R1 Cumprimento: 90–110% verde · 80–90% laranja · < 80% ou ≥ 110% vermelho; sem plano → var(--text-muted) | N5: #34d399 | O5: Tornar o cartão principal (opt-summary-card-main), neutro; aplicar getCumprimentoColor() só ao número. Acima de 101% passa de amarelo a verde até 110% e vermelho daí para cima. | P5: Alta | Q5: S | R5: Por fazer
A6: K02 | B6: Métricas | C6: PEÇAS PLANEADAS | D6: kpiQtdPlaneada | E6: .kpi-card | F6: #ffffff | G6: 5px #005a9e | H6: text-dark | I6: 0.65rem / 1.8rem | J6: Sem regra | K6: Qtd. Planeada no cartão duplo do Histórico (ponto azul) | L6: .opt-kpi-dual dentro de .opt-summary-card: 2 linhas rótulo 0.78rem 700 maiúsculas + valor 1.35rem 800 var(--text-strong); ponto .opt-kpi-dot | M6: Sem regra; ponto .opt-kpi-dot-plan #38bdf8 | N6: var(--text-strong) | O6: Juntar K02 e K03 num só cartão duplo (Produzida em cima com ponto verde, Planeada em baixo com ponto azul) — igual ao Histórico. Elimina as barras laterais azul/verde. | P6: Alta | Q6: M | R6: Por fazer
A7: K03 | B7: Métricas | C7: PEÇAS PRODUZIDAS | D7: kpiQtdProduzida | E7: .kpi-card | F7: #ffffff | G7: 5px #10b981 | H7: text-dark | I7: 0.65rem / 1.8rem | J7: Sem regra | K7: Qtd. Produzida no cartão duplo do Histórico (ponto verde) | L7: .opt-kpi-dual dentro de .opt-summary-card: 2 linhas rótulo 0.78rem 700 maiúsculas + valor 1.35rem 800 var(--text-strong); ponto .opt-kpi-dot | M7: Sem regra; ponto .opt-kpi-dot-prod #34d399 | N7: var(--text-strong) | O7: Ver K02. | P7: Alta | Q7: M | R7: Por fazer
A8: K04 | B8: Métricas · Cumprimento de Prazos | C8: LOGÍSTICA (Quarta 12h00) | D8: kpiLogisticaPct / kpiStandardLogisticaCard | E8: .kpi-card (horizontal) | F8: #fff → semáforo | G8: 5px #0dcaf0 → semáforo | H8: #0dcaf0 → #0f5132 / #856404 / #842029 | I8: 0.65rem / 1.8rem | J8: Sem dados: ciano · > 101% amarelo · ≥ 90% verde · ≥ 80% amarelo · < 80% vermelho (fundo + barra + número) | K8: % Produzido no Prazo (Histórico) — conceito de pontualidade | L8: .opt-summary-card (fundo var(--bg-card), borda 1px var(--border-color), raio 8px, centrado); título .title 0.82rem 700 var(--text-label) maiúsculas; valor .value 1.7rem 800; texto "N de M (QUARTA 12H00)" em 0.72rem var(--text-muted) por baixo do valor | M8: R2 Pontualidade de comunicação: ≥ 90% verde · 80–90% laranja · < 80% vermelho; sem registos → var(--text-muted) | N8: #34d399 | O8: Cartão neutro, cor só no número. NÃO copiar getPontualidadeColor (põe 100% a vermelho, só faz sentido no statusOPT). Banda "> 101%" desaparece (uma % de cumprimento nunca passa de 100). | P8: Alta | Q8: S | R8: Por fazer
A9: K05 | B9: Métricas · Cumprimento de Prazos | C9: PRODUÇÃO (Quinta 14h30) | D9: kpiProducaoPct / kpiStandardProducaoCard | E9: .kpi-card (horizontal) | F9: #fff → semáforo | G9: 5px #fd7e14 → semáforo | H9: #fd7e14 → #0f5132 / #856404 / #842029 | I9: 0.65rem / 1.8rem | J9: Igual a K04 (sem dados: laranja) | K9: % Produzido no Prazo (Histórico) | L9: .opt-summary-card (fundo var(--bg-card), borda 1px var(--border-color), raio 8px, centrado); título .title 0.82rem 700 var(--text-label) maiúsculas; valor .value 1.7rem 800 | M9: R2 (igual a K04) | N9: #34d399 | O9: Igual a K04. O laranja "sem dados" engana: parece alerta quando só não há registos. | P9: Alta | Q9: S | R9: Por fazer
A10: K06 | B10: Métricas · Operadores | C10: Nº OPERADORES LOGÍSTICA | D10: kpiOperadoresLogistica | E10: .kpi-card | F10: #ffffff | G10: 5px #0284c7 | H10: text-dark | I10: 0.65rem / 1.8rem | J10: Sem regra | K10: Contagens neutras (ex.: Ensaios no cabeçalho) | L10: .opt-kpi-dual dentro de .opt-summary-card: 2 linhas rótulo 0.78rem 700 maiúsculas + valor 1.35rem 800 var(--text-strong); ponto .opt-kpi-dot | M10: Sem regra | N10: var(--text-strong) | O10: Juntar K06 e K07 num cartão duplo "Operadores" (Logística / Produção), valores em var(--text-strong), sem barras laterais. | P10: Média | Q10: S | R10: Por fazer
A11: K07 | B11: Métricas · Operadores | C11: Nº OPERADORES PRODUÇÃO | D11: kpiOperadoresProducao | E11: .kpi-card | F11: #ffffff | G11: 5px #fd7e14 | H11: text-dark | I11: 0.65rem / 1.8rem | J11: Sem regra | K11: Contagens neutras | L11: .opt-kpi-dual dentro de .opt-summary-card: 2 linhas rótulo 0.78rem 700 maiúsculas + valor 1.35rem 800 var(--text-strong); ponto .opt-kpi-dot | M11: Sem regra | N11: var(--text-strong) | O11: Ver K06. | P11: Média | Q11: S | R11: Por fazer
A12: K08 | B12: Análise de Turnos | C12: COBERTURA DE TURNOS SOLICITADOS (%) | D12: kpiNecPreenchidosPct / kpiNecPreenchidosCard | E12: .kpi-card.highlight-card | F12: #f8d7da → semáforo | G12: #dc3545 → semáforo | H12: text-dark (fixo) | I12: 0.65rem / 2.2rem | J12: Igual a K01 (fundo + barra) | K12: Qtd. PRODUZIDO/PLANEADO (%) — mesmo conceito (obtido ÷ pedido) | L12: .opt-summary-card.opt-summary-card-main (borda ciano + brilho; título ciano; valor 2.1rem 800) | M12: R1 Cumprimento | N12: #34d399 | O12: Cartão principal da linha de turnos, neutro, número colorido por getCumprimentoColor(). | P12: Alta | Q12: S | R12: Por fazer
A13: K09 | B13: Análise de Turnos | C13: ∑ TURNOS SOLICITADOS | D13: kpiTurnosNec | E13: sub-bloco em .kpi-card | F13: #ffffff | G13: 3px #64b5f6 | H13: text-dark | I13: 0.6rem / 1.5rem | J13: Sem regra | K13: Qtd. Planeada (cartão duplo) — "o que foi pedido" | L13: .opt-kpi-dual dentro de .opt-summary-card: 2 linhas rótulo 0.78rem 700 maiúsculas + valor 1.35rem 800 var(--text-strong); ponto .opt-kpi-dot | M13: Ponto azul #38bdf8 (= planeado/pedido) | N13: var(--text-strong) | O13: Cartão duplo: Garantidos (ponto verde) em cima, Solicitados (ponto azul) em baixo — mesma ordem e cores do Histórico. | P13: Média | Q13: S | R13: Por fazer
A14: K10 | B14: Análise de Turnos | C14: ∑ TURNOS GARANTIDOS | D14: kpiTotalPreenchidos | E14: sub-bloco em .kpi-card | F14: #ffffff | G14: 3px #005a9e | H14: text-dark | I14: 0.6rem / 1.5rem | J14: Sem regra | K14: Qtd. Produzida (cartão duplo) — "o que foi conseguido" | L14: .opt-kpi-dual dentro de .opt-summary-card: 2 linhas rótulo 0.78rem 700 maiúsculas + valor 1.35rem 800 var(--text-strong); ponto .opt-kpi-dot | M14: Ponto verde #34d399 | N14: var(--text-strong) | O14: Ver K09. | P14: Média | Q14: S | R14: Por fazer
A15: K11 | B15: Análise de Turnos | C15: TURNOS SOLICITADOS FIM DE SEMANA | D15: kpiFimSemana | E15: sub-bloco em .kpi-card | F15: #ffffff | G15: 3px #81c784 | H15: text-dark | I15: 0.6rem / 1.5rem | J15: Sem regra | K15: Qtd. Planeada (cartão duplo) | L15: .opt-kpi-dual dentro de .opt-summary-card: 2 linhas rótulo 0.78rem 700 maiúsculas + valor 1.35rem 800 var(--text-strong); ponto .opt-kpi-dot | M15: Ponto azul #38bdf8 | N15: var(--text-strong) | O15: Hoje cada par tem a sua cor (azul/verde/amarelo) sem significado de estado. Uniformizar: o papel (solicitado/garantido) define a cor, não a categoria. | P15: Média | Q15: S | R15: Por fazer
... A22: K18 | B22: Tabela Plano | C22: Produzido/Planeado (%) por linha | D22: #tablePlano td | E22: badge | F22: bg-success / bg-warning / bg-danger | G22: — | H22: branco / text-dark | I22: — | J22: > 101% amarelo · ≥ 90% verde · ≥ 80% amarelo · < 80% vermelho | K22: getCumprimentoBadgeClass() nos popups | L22: badge Bootstrap | M22: R1 Cumprimento em versão badge: bg-success 90–110 · bg-warning text-dark 80–90 · bg-danger resto | N22: — | O22: Trocar a função de classe pela getCumprimentoBadgeClass() do statusOPT — mesmo limiar que K01. | P22: Média | Q22: S | R22: Por fazer
A24: Esforço: S = minutos (trocar classes/cores) · M = mexer no HTML do cartão · L = reescrita de componente.

Sheet Ref. statusOPT
A1: Referência: como o statusOPT pinta cada um dos seus indicadores
A2: Levantamento do ficheiro de referência, para consulta ao adaptar o painel.
A4: Vista | B4: Indicador | C4: Elemento (id) | D4: Componente | E4: Cor do valor | F4: Amostra (escuro) | G4: Regra | H4: Ícone | I4: Nota
A5: Dashboard | B5: ÁREA | C5: opt-areaButtons | D5: .opt-summary-card + .opt-area-btn | E5: var(--cyan-accent) | F5: #22d3ee | G5: Botão contorno ciano 1.05rem 800; ativo = fundo ciano, texto var(--on-accent) | H5: —
A6: Dashboard | B6: TOTAL EM ATRASO [ÁREA] | C6: opt-kpiTotalDelta | D6: .opt-summary-card | E6: #34d399 / #fb923c / #f87171 | F6: #f87171 | G6: Soma só atrasos: 0 → verde · > −8h laranja · ≤ −8h vermelho | H6: fa-circle-check / fa-triangle-exclamation / fa-circle-minus
A7: Dashboard | B7: % CC em atraso > 8H | C7: opt-kpiCcAtraso8h | D7: .opt-summary-card.clickable | E7: #34d399 / #fd7e14 / #f87171 | F7: #fd7e14 | G7: 0% verde · > 0% laranja · ≥ 80% vermelho (quanto maior, pior) | H7: — | I7: Usa #fd7e14 em vez do laranja comum #fb923c
A8: Dashboard | B8: Qtd. PRODUZIDO/PLANEADO (%) | C8: opt-kpiQtdRatio | D8: .opt-summary-card.clickable | E8: getCumprimentoColor | F8: #34d399 | G8: 90–110% verde · 80–90% laranja · resto vermelho · sem plano var(--text-muted) | H8: —
A9: Dashboard | B9: Disponibilidade MP | C9: opt-kpiDispMP | D9: .opt-summary-card.clickable | E9: getKpiColor | F9: #34d399 | G9: < 50% vermelho · < 80% laranja · ≥ 80% verde | H9: —
A10: Dashboard | B10: Disponibilidade FRT | C10: opt-kpiDispFRT | D10: .opt-summary-card.clickable | E10: getKpiColor | F10: #34d399 | G10: Igual a MP | H10: —
A11: Dashboard | B11: Desvio do CC (avanço/atraso) | C11: .opt-cc-stat-destaque | D11: .opt-cc-stat (0.66rem rótulo / 1.1rem valor) | E11: getDelayCardConfig | F11: #fb923c | G11: ≥ 0 verde · > −8h laranja · ≤ −8h vermelho | H11: fa-circle-plus / fa-triangle-exclamation / fa-circle-minus | I11: Fundo var(--bg-subtle), hover borda ciano
A12: Dashboard | B12: Backlog do CC | C12: .opt-cc-backlog | D12: Faixa: fundo rgba(251,146,60,.1), borda esq. 3px #fb923c | E12: #fb923c | F12: #fb923c | G12: Sempre laranja (é trabalho em falta) | H12: fa-layer-group
A13: Cabeçalho | B13: Atualizado a | C13: .opt-header-status | D13: Pílula var(--bg-inset) 0.85rem | E13: var(--text-muted) / #fb923c / #f87171 | F13: #94a3b8 | G13: < 45 min neutro · ≥ 45 min laranja · ≥ 90 min vermelho | H13: fa-clock | I13: Recomendado também no painel
A14: Cabeçalho | B14: Backlog / Ensaios | C14: opt-lblBacklog / opt-lblEnsaios | D14: .opt-header-status.opt-clickable-status | E14: #fb923c se houver / var(--text-strong) | F14: #fb923c | G14: Com itens → laranja | H14: fa-layer-group / fa-flask
A15: Dashboard | B15: Previsão de Trabalho Extra | C15: opt-tableTrabalhoExtra | D15: Tabela branca fixa, cabeçalho #0f172a | E15: #ef4444 / #22c55e | F15: #ef4444 | G15: Previsão > 0 vermelho · 0 verde; restantes colunas #0f172a | H15: — | I15: Não segue o tema (sempre branca)
A16: Dashboard | B16: MOD Planeada | C16: opt-tableMOD | D16: .table-mod | E16: células #059669 / #d97706 / branco | F16: #059669 | G16: Verde OK · laranja falta · branco sem dados | H16: —
A17: Dashboard | B17: Material em risco | C17: opt-tableRisk | D17: .opt-risk-container borda 2px #ef4444 | E17: #dc2626 / #d97706 | F17: #dc2626 | G17: .risk-badge-critical / .risk-badge-warning | H17: fa-triangle-exclamation
A18: Dashboard | B18: Status (Planeado, Preparada, Em curso, Produzido, Interrompido) | C18: badge | D18: .badge.opt-badge-status | E18: #999999 · #f58231 · #ffe119 · #33cc00 · #ff0000 | F18: #33cc00 | G18: Cores da própria lista SharePoint | H18: —
A19: Histórico | B19: PRODUZIDO/PLANEADO | C19: hist-kpiCumprimento | D19: .opt-summary-card-main.clickable | E19: getKpiColor | F19: #34d399 | G19: < 50% vermelho · < 80% laranja · ≥ 80% verde | H19: fa-percent | I19: INCONSISTÊNCIA: o Dashboard usa getCumprimentoColor para o mesmo indicador (130% fica verde aqui e vermelho lá)
A20: Histórico | B20: Qtd. Produzida / Qtd. Planeada | C20: hist-kpiQtdProduzida / hist-kpiQtdPlaneada | D20: .opt-kpi-dual | E20: var(--text-strong) | F20: #e2e8f0 | G20: Neutro; pontos #34d399 (produzida) / #38bdf8 (planeada) | H20: fa-boxes-packing / fa-boxes-stacked | I20: Modelo para K02/K03, K06/K07, K09–K14
A21: Histórico | B21: % Produzido no Prazo | C21: hist-kpiPontualidade | D21: .opt-summary-card.clickable | E21: getPontualidadeColor | F21: #34d399 | G21: 90–100% verde · 80–90% laranja · < 80% ou ≥ 100% vermelho | H21: fa-calendar-check
A22: Histórico | B22: Média Dias Atraso | C22: hist-kpiMediaAtraso | D22: .opt-summary-card.clickable | E22: getAtrasoColor | F22: #fb923c | G22: ≤ 0 d verde · ≤ 1 d laranja · > 1 d vermelho | H22: fa-clock
A23: Histórico | B23: Caixa de Erros | C23: hist-kpiProduzidoSemQtd | D23: .opt-summary-card.clickable | E23: #34d399 / #fb923c | F23: #34d399 | G23: 0 verde · > 0 laranja | H23: fa-triangle-exclamation
A24: Histórico | B24: Disponibilidade MP / FRT | C24: hist-kpiDispMPFRT | D24: .opt-summary-card.clickable (valor 1.15rem) | E24: var(--text-strong) | F24: #e2e8f0 | G24: Neutro | H24: fa-boxes-stacked

Sheet Regras de Cor
A1: Regras de semáforo: o que existe em cada ficheiro e o que adotar no painel
A2: Uma linha por banda. As amostras são as cores do statusOPT; os contrastes são calculados (WCAG 2.1) sobre o cartão escuro (#1e293b) e branco.
A4: Regra | B4: Origem | C4: Aplica-se a | D4: Banda | E4: Condição | F4: Cor | G4: Amostra | H4: Contraste escuro | I4: Contraste claro | J4: Nota
A5: R1 Cumprimento (ADOTAR) | B5: statusOPT | C5: K01, K08, K18 — e linha % Cobertura nos pontos | D5: OK | E5: 90% ≤ x < 110% | F5: #34d399 | H5: 7.61 | I5: 1.92 | J5: getCumprimentoColor() / getCumprimentoBadgeClass(). Excesso também é desvio ao plano.
D6: Atenção | E6: 80% ≤ x < 90% | F6: #fb923c | H6: 6.46 | I6: 2.26
D7: Fora | E7: x < 80% ou x ≥ 110% | F7: #f87171 | H7: 5.29 | I7: 2.77
D8: Sem dados | E8: nada planeado | F8: #94a3b8 | H8: 5.71 | I8: 2.56
A9: R2 Pontualidade comunicação (PROPOSTA) | B9: Proposta | C9: K04, K05 | D9: OK | E9: x ≥ 90% | F9: #34d399 | H9: 7.61 | I9: 1.92 | J9: Mesmos limiares e cores do statusOPT, sem teto (100% é o ideal). Não existe função igual no statusOPT.
D10: Atenção | E10: 80% ≤ x < 90% | F10: #fb923c | H10: 6.46 | I10: 2.26
D11: Fora | E11: x < 80% | F11: #f87171 | H11: 5.29 | I11: 2.77
D12: Sem dados | E12: 0 registos | F12: #94a3b8 | H12: 5.71 | I12: 2.56
A13: R3 Desvio de turnos (DECIDIR) | B13: statusOPT adaptado | C13: K15, K16 | D13: Avanço / igual | E13: Δ ≥ 0 | F13: #34d399 | H13: 7.61 | I13: 1.92 | J13: Copia getDelayCardConfig(). O statusOPT usa −8h; para turnos sugere-se −3 (≈ 1 dia a 3 turnos). Alternativa: manter 3 estados e pôr o excesso (Δ > 0) a ciano #22d3ee em vez de verde.
D14: Atraso leve | E14: −3 < Δ < 0 (limiar a confirmar) | F14: #fb923c | H14: 6.46 | I14: 2.26
D15: Atraso grave | E15: Δ ≤ −3 (limiar a confirmar) | F15: #f87171 | H15: 5.29 | I15: 2.77
A16: Painel atual — Adesão / Cobertura | B16: Painel TE | C16: K01, K08, K18 | D16: Excesso | E16: x > 101% | F16: #ffc107 | H16: 8.97 | I16: 1.63 | J16: Pinta fundo + barra; o número fica preto. Amarelo usado para duas coisas diferentes.
D17: OK | E17: 90% ≤ x ≤ 101% | F17: #198754 | H17: 3.23 | I17: 4.53
D18: Atenção | E18: 80% ≤ x < 90% | F18: #ffc107 | H18: 8.97 | I18: 1.63
D19: Fora | E19: x < 80% | F19: #dc3545 | H19: 3.23 | I19: 4.53
A20: Painel atual — Logística / Produção | B20: Painel TE | C20: K04, K05 | D20: Sem dados | E20: 0 registos | F20: #0dcaf0 | H20: 7.47 | I20: 1.96 | J20: A banda > 101% nunca acontece (% de registos a horas). "Sem dados" tem cor de identidade, parece um valor.
D21: Excesso | E21: x > 101% | F21: #ffc107 | H21: 8.97 | I21: 1.63
D22: OK | E22: x ≥ 90% | F22: #198754 | H22: 3.23 | I22: 4.53
D23: Atenção | E23: x ≥ 80% | F23: #ffc107 | H23: 8.97 | I23: 1.63
D24: Fora | E24: x < 80% | F24: #dc3545 | H24: 3.23 | I24: 4.53
A25: Painel atual — Δ Turnos | B25: Painel TE | C25: K15, K16 | D25: Falta | E25: Δ < 0 | F25: #dc3545 | H25: 3.23 | I25: 4.53 | J25: Título do cartão fica sempre #842029, mesmo com Δ positivo.
D26: Excesso | E26: Δ > 0 | F26: #0d6efd | H26: 3.25 | I26: 4.5
D27: Igual | E27: Δ = 0 | F27: #198754 | H27: 3.23 | I27: 4.53
A28: getKpiColor | B28: statusOPT | C28: Disp. MP, Disp. FRT, Hist. PRODUZIDO/PLANEADO | D28: Fora | E28: x < 50% | F28: #f87171 | H28: 5.29 | I28: 2.77 | J28: Referência.
D29: Atenção | E29: 50% ≤ x < 80% | F29: #fb923c | H29: 6.46 | I29: 2.26
D30: OK | E30: x ≥ 80% | F30: #34d399 | H30: 7.61 | I30: 1.92
A31: getAtraso8hColor | B31: statusOPT | C31: % CC em atraso > 8H | D31: OK | E31: x = 0% | F31: #34d399 | H31: 7.61 | I31: 1.92 | J31: Indicador invertido (maior = pior).
D32: Atenção | E32: 0% < x < 80% | F32: #fd7e14 | H32: 5.69 | I32: 2.57
D33: Fora | E33: x ≥ 80% | F33: #f87171 | H33: 5.29 | I33: 2.77
A34: getPontualidadeColor | B34: statusOPT | C34: Hist. % Produzido no Prazo | D34: OK | E34: 90% ≤ x < 100% | F34: #34d399 | H34: 7.61 | I34: 1.92 | J34: Não reutilizar no painel (100% fica vermelho).
D35: Atenção | E35: 80% ≤ x < 90% | F35: #fb923c | H35: 6.46 | I35: 2.26
D36: Fora | E36: x < 80% ou x ≥ 100% | F36: #f87171 | H36: 5.29 | I36: 2.77
A37: getAtrasoColor | B37: statusOPT | C37: Hist. Média Dias Atraso | D37: OK | E37: d ≤ 0 | F37: #34d399 | H37: 7.61 | I37: 1.92 | J37: Referência.
D38: Atenção | E38: 0 < d ≤ 1 | F38: #fb923c | H38: 6.46 | I38: 2.26
D39: Fora | E39: d > 1 | F39: #f87171 | H39: 5.29 | I39: 2.77
A41: Notas
A42: N1 — Contraste no tema claro: as cores fixas do statusOPT (#34d399, #fb923c, #fd7e14) ficam abaixo de 3:1 sobre branco (valores a vermelho na coluna). O statusOPT já tem tons escuros para o tema claro nos botões (--btn-success #15803d, --btn-warning #b45309, --btn-danger #b91c1c). Sugestão para os dois ficheiros: criar --kpi-ok / --kpi-alerta / --kpi-critico com esses tons no tema claro, e as funções get…Color() passarem a ler corTema().
...

Sheet Gráficos
A1: Gráficos do painel: cores e estilo atuais → statusOPT
A2: No statusOPT os eixos, grelha, legendas e rótulos leem as cores do tema com corTema(); os gráficos são redesenhados quando o tema muda.
A4: ID | B4: Gráfico | C4: Canvas | D4: Tipo | E4: Cores atuais | F4: Amostra atual | G4: Rótulos / eixos atuais | H4: Equivalente statusOPT | I4: Cores a aplicar | J4: Amostra nova | K4: Rótulos / eixos a aplicar | L4: Prioridade | M4: Estado
A5: G01 | B5: Evolução por Semana/Mês (% Planeado vs Produzido) | C5: chartEvolucaoAdesao | D5: linha | E5: #005a9e, fill rgba(0,90,158,.1) | F5: #005a9e | G5: datalabels #1e293b bold 11 · ticks/grelha por defeito do Chart.js (#666, rgba(0,0,0,.1)) — ilegível em fundo escuro | H5: Evolução Temporal (Histórico) | I5: #22d3ee, fill rgba(34,211,238,.15), tension .3; pontos coloridos por R1 | J5: #22d3ee | K5: datalabels corTema('--chart-text-strong') bold 11 · ticks corTema('--chart-text') · grid corTema('--chart-grid') (x sem grelha nas barras) · 'Sem dados' corTema('--chart-empty') 14 | L5: Alta | M5: Por fazer
A6: G02 | B6: % Planeado vs Produzido por Área | C6: chartAdesaoArea | D6: barras | E6: #005a9e; selecionada #003d6b | F6: #005a9e | G6: datalabels #1e293b bold 11 · ticks/grelha por defeito do Chart.js (#666, rgba(0,0,0,.1)) — ilegível em fundo escuro | H6: % Planeado vs Produzido por Área (Histórico) | I6: #22d3ee; não selecionadas rgba(34,211,238,.35) | J6: #22d3ee | K6: datalabels corTema('--chart-text-strong') bold 11 · ticks corTema('--chart-text') · grid corTema('--chart-grid') (x sem grelha nas barras) · 'Sem dados' corTema('--chart-empty') 14 | L6: Alta | M6: Por fazer
A7: G03 | B7: % Planeado vs Produzido por C.C. | C7: chartAdesaoCC | D7: barras | E7: #10b981 | F7: #10b981 | G7: datalabels #1e293b bold 11 · ticks/grelha por defeito do Chart.js (#666, rgba(0,0,0,.1)) — ilegível em fundo escuro | H7: % Planeado vs Produzido por C.C. (Histórico) | I7: #34d399 | J7: #34d399 | K7: datalabels corTema('--chart-text-strong') bold 11 · ticks corTema('--chart-text') · grid corTema('--chart-grid') (x sem grelha nas barras) · 'Sem dados' corTema('--chart-empty') 14 · badge bg-success com a área filtrada no título | L7: Alta | M7: Por fazer
A8: G04 | B8: Evolução por Semana/Mês (Turnos Extra) | C8: chartEvolucao | D8: linha | E8: Solic. #64b5f6 · Garant. #005a9e | F8: #64b5f6 | G8: datalabels #1e293b bold 11 · ticks/grelha por defeito do Chart.js (#666, rgba(0,0,0,.1)) — ilegível em fundo escuro | H8: Evolução Temporal: Planeada #22d3ee / Produzida #34d399 | I8: Solic. #22d3ee · Garant. #34d399, fill .15 | J8: #34d399 | K8: datalabels corTema('--chart-text-strong') bold 11 · ticks corTema('--chart-text') · grid corTema('--chart-grid') (x sem grelha nas barras) · 'Sem dados' corTema('--chart-empty') 14 · legenda corTema(--chart-text-strong) | L8: Alta | M8: Por fazer
A9: G05 | B9: Turnos por Área | C9: chartAreas | D9: barras | E9: #005a9e; selecionada #003d6b | F9: #005a9e | G9: datalabels #1e293b bold 11 · ticks/grelha por defeito do Chart.js (#666, rgba(0,0,0,.1)) — ilegível em fundo escuro | H9: Barras por Área | I9: #22d3ee; não selecionadas .35 | J9: #22d3ee | K9: datalabels corTema('--chart-text-strong') bold 11 · ticks corTema('--chart-text') · grid corTema('--chart-grid') (x sem grelha nas barras) · 'Sem dados' corTema('--chart-empty') 14 | L9: Média | M9: Por fazer
A10: G06 | B10: Turnos por C.C. | C10: chartCC | D10: barras | E10: #10b981 | F10: #10b981 | G10: datalabels #1e293b bold 11 · ticks/grelha por defeito do Chart.js (#666, rgba(0,0,0,.1)) — ilegível em fundo escuro | H10: Barras por C.C. | I10: #34d399 | J10: #34d399 | K10: datalabels corTema('--chart-text-strong') bold 11 · ticks corTema('--chart-text') · grid corTema('--chart-grid') (x sem grelha nas barras) · 'Sem dados' corTema('--chart-empty') 14 | L10: Média | M10: Por fazer
A11: G07 | B11: Evolução Cobertura de Turnos Solicitados (%) | C11: chartEvolucaoNecPreenchidos | D11: linha | E11: #dc3545, fill rgba(220,53,69,.1) | F11: #dc3545 | G11: datalabels #1e293b bold 11 · ticks/grelha por defeito do Chart.js (#666, rgba(0,0,0,.1)) — ilegível em fundo escuro | H11: — (não há) | I11: Linha #22d3ee; pointBackgroundColor por R1 (verde/laranja/vermelho) | J11: #22d3ee | K11: datalabels corTema('--chart-text-strong') bold 11 · ticks corTema('--chart-text') · grid corTema('--chart-grid') (x sem grelha nas barras) · 'Sem dados' corTema('--chart-empty') 14 | L11: Média | M11: Por fazer
A12: G08 | B12: Turnos por Motivo | C12: chartMotivos | D12: donut | E12: #005a9e #10b981 #f59e0b #dc3545 #64748b #0284c7 #8b5cf6 #ec4899 | F12: #f59e0b | G12: datalabels #fff; sem borda entre fatias; legenda por defeito | H12: Causa Raiz dos Desvios (Histórico) | I12: #22d3ee #a78bfa #f87171 #fb923c #34d399 #facc15 #60a5fa #f472b6 #94a3b8 #4ade80 #c084fc #fb7185 | J12: #a78bfa | K12: datalabels #0f172a bold 11 · borderColor corTema('--bg-card') largura 2 · legenda em baixo corTema('--chart-text-strong') 10 | L12: Média | M12: Por fazer
A13: G09 | B13: Operadores por Turno | C13: chartOpsProducaoTurno | D13: barras | E13: Logística #0284c7 · Produção #fd7e14 | F13: #0284c7 | G13: datalabels #1e293b bold 11 · ticks/grelha por defeito do Chart.js (#666, rgba(0,0,0,.1)) — ilegível em fundo escuro · legenda em baixo | H13: — (séries de identidade) | I13: Logística #22d3ee · Produção #fb923c | J13: #fb923c | K13: datalabels corTema('--chart-text-strong') bold 11 · ticks corTema('--chart-text') · grid corTema('--chart-grid') (x sem grelha nas barras) · 'Sem dados' corTema('--chart-empty') 14 | L13: Média | M13: Por fazer
A14: G10 | B14: Operadores Produção por Área | C14: chartOpsProducaoArea | D14: barras | E14: #005a9e; selecionada #003d6b | F14: #005a9e | G14: datalabels #1e293b bold 11 · ticks/grelha por defeito do Chart.js (#666, rgba(0,0,0,.1)) — ilegível em fundo escuro | H14: Barras por Área | I14: #22d3ee; não selecionadas .35 | J14: #22d3ee | K14: datalabels corTema('--chart-text-strong') bold 11 · ticks corTema('--chart-text') · grid corTema('--chart-grid') (x sem grelha nas barras) · 'Sem dados' corTema('--chart-empty') 14 | L14: Média | M14: Por fazer
A15: G11 | B15: Operadores Produção por C.C. | C15: chartOpsProducaoCC | D15: barras | E15: #10b981 | F15: #10b981 | G15: datalabels #1e293b bold 11 · ticks/grelha por defeito do Chart.js (#666, rgba(0,0,0,.1)) — ilegível em fundo escuro | H15: Barras por C.C. | I15: #34d399 | J15: #34d399 | K15: datalabels corTema('--chart-text-strong') bold 11 · ticks corTema('--chart-text') · grid corTema('--chart-grid') (x sem grelha nas barras) · 'Sem dados' corTema('--chart-empty') 14 | L15: Média | M15: Por fazer
A17: Paletas lado a lado
B18: Painel TE (Motivos) | C18: #005a9e | D18: #10b981 | E18: #f59e0b | F18: #dc3545 | G18: #64748b | H18: #0284c7 | I18: #8b5cf6 | J18: #ec4899
B19: statusOPT (Causa Raiz) | C19: #22d3ee | D19: #a78bfa | E19: #f87171 | F19: #fb923c | G19: #34d399 | H19: #facc15 | I19: #60a5fa | J19: #f472b6 | K19: #94a3b8 | L19: #4ade80 | M19: #c084fc | N19: #fb7185

Sheet Componentes
A1: Componentes de interface: painel atual vs statusOPT
A2: Estrutura, superfícies, bordas, raios, espaçamentos e tipografia de cada bloco.
A4: ID | B4: Componente | C4: Painel TE (atual) | D4: statusOPT (referência) | E4: Diferença | F4: Ação recomendada | G4: Prioridade | H4: Esforço | I4: Estado
A5: C01 | B5: Tema / fundo da página | C5: Só tema claro. --sp-bg #f4f6f9; texto #333; cores escritas à mão em todo o CSS/JS (~40 cores diferentes). | D5: Tema escuro por defeito + tema claro; ~27 variáveis em :root e :root[data-theme=light]; html/body/#s4-workspace com var(--sp-bg) !important. | E5: Sem tema escuro, sem variáveis. | F5: Copiar os dois blocos :root do statusOPT e trocar todas as cores por var(--…) (folha "Cores Painel TE"). | G5: Alta | H5: M | I5: Por fazer
A6: C02 | B6: Interruptor de tema | C6: Não existe. | D6: .opt-tema-switch 62×30, puxador 22px, sol/lua; preferência em localStorage "opt_tema_v1"; gráficos redesenhados ao trocar. | E6: Em falta. | F6: Copiar markup, CSS e aplicarTema(). Usar a MESMA chave "opt_tema_v1": no mesmo site SharePoint o localStorage é partilhado e o tema escolhido num painel aplica-se ao outro. | G6: Alta | H6: S | I6: Por fazer
A7: C03 | B7: Cabeçalho | C7: .dashboard-header: branco, raio 10, padding 20/25, borda esq. 6px #005a9e; h2 fw-bold text-dark com ícone text-primary; subtítulo muted. | D7: .opt-header-bar: var(--bg-card), raio 8, padding 12/20, borda 1px; título .opt-header-title var(--cyan-accent) 1.3rem 700 letter-spacing .5px com fa-industry. | E7: Barra lateral azul, título preto e maior (h2 ≈ 2rem). | F7: Trocar para .opt-header-bar + .opt-header-title; subtítulo em pílula .opt-week-badge ou small var(--text-muted). | G7: Alta | H7: S | I7: Por fazer
A8: C04 | B8: Indicador "Atualizado a" | C8: Não existe. | D8: .opt-header-status (pílula var(--bg-inset) 0.85rem) por cima do cabeçalho, laranja ≥ 45 min, vermelho ≥ 90 min. | E8: Em falta. | F8: Acrescentar a pílula com a hora do último carregamento (só estilo + 1 linha em loadData). | G8: Média | H8: S | I8: Por fazer
A9: C05 | B9: Botões do cabeçalho | C9: Ecrã Inteiro: btn-outline-secondary btn-sm fw-bold; Atualizar: btn-outline-primary (azul Bootstrap #0d6efd). | D9: Mesmas classes, mas redefinidas: outline-primary = var(--cyan-accent), hover fundo ciano / texto var(--on-accent); outline-secondary = var(--btn-secondary). | E9: Classes iguais, cores não. | F9: Copiar o bloco "FORMULÁRIOS E OVERRIDES BOOTSTRAP" (.btn-outline-*, .btn-*, .text-primary, .text-success, .text-muted, .text-dark). | G9: Alta | H9: S | I9: Por fazer
A10: C06 | B10: Barra de filtros | C10: .filter-section branco, raio 10, sticky top 10px; a classe border-0 do HTML anula a borda #005a9e do CSS. Rótulos 0.75rem maiúsculas muted com ícone text-primary. | D10: .opt-hist-filter-bar: var(--bg-card), raio 10, padding 10/15, borda 1px, sticky top 0, z-index 1030; rótulos 0.72rem 700 maiúsculas var(--text-muted). | E10: Muito próximo; muda fundo, borda e tamanho do rótulo. | F10: Aplicar .opt-hist-filter-bar (ou copiar as suas regras para .filter-section) e retirar border-0/bg-white do HTML. | G10: Média | H10: S | I10: Por fazer
A11: C07 | B11: Multiselect dos filtros | C11: Dropdown Bootstrap: botão branco borda #ced4da 0.85rem; menu branco; "Selecionar Tudo" btn-link azul; "Limpar" text-danger. | D11: .opt-ms-toggle var(--bg-inset) borda var(--border-color) raio 6 0.85rem com chevron; painel var(--bg-elevated); ações em links var(--cyan-accent) 0.72rem; checkbox accent-color ciano. | E11: Cores e acabamento. | F11: Manter o componente do painel e pintá-lo com as variáveis (fundo inset, menu elevated, links ciano, accent-color). | G11: Média | H11: M | I11: Por fazer
A12: C08 | B12: Secções (acordeão) | C12: .accordion-item sombra, raio 10; botão 1.05rem 700 #1e293b em branco com borda esq. 5px #005a9e; aberto: #005a9e sobre #eef5fc; corpo #f8fafc. | D12: Títulos colapsáveis .opt-mod-title (var(--cyan-accent) 1rem 700, ícone text-primary, chevron muted) dentro de .opt-mod-container (var(--bg-card), raio 10, borda 1px); acordeão de CC .accordion-btn-cc var(--bg-inset) texto ciano. | E12: Barra lateral azul e fundos claros fixos. | F12: Botão: fundo var(--bg-inset), texto var(--cyan-accent) 1rem 700, sem borda lateral; aberto var(--bg-card); item com borda 1px var(--border-color); corpo var(--sp-bg). Seta com o filtro ciano do statusOPT. | G12: Alta | H12: S | I12: Por fazer
A13: C09 | B13: Etiqueta de grupo (.section-tag) | C13: Pílula #475569 sobre #e2e8f0, 0.68–0.75rem 700 ("Cumprimento de Prazos", "Operadores", "Análise de Turnos"). | D13: .opt-hist-section-title (var(--cyan-accent) 1rem 700 com ícone) para títulos de bloco; .opt-cc-stat-label (0.66rem 700 maiúsculas var(--text-muted)) para rótulos pequenos. | E13: Pílula cinzenta não existe no statusOPT. | F13: "Análise de Turnos" → .opt-hist-section-title; "Cumprimento de Prazos" e "Operadores" → rótulo pequeno em var(--text-muted). | G13: Média | H13: S | I13: Por fazer
A14: C10 | B14: Cartão KPI (base) | C14: .kpi-card branco, raio 8, padding 14, borda esq. 4–8px colorida, hover translateY(-2px) em TODOS; títulos 0.6–0.85rem (inline), valores 1.5–2.8rem. | D14: .opt-summary-card var(--bg-card), raio 8, padding 12/10, centrado, borda 1px; título 0.82rem 700 var(--text-label); valor 1.7rem 800; hover só em .clickable (-3px + borda ciano). | E14: 6 tamanhos de título e 5 de valor diferentes; barras laterais; hover sem ação. | F14: Ver folha "KPIs Painel TE". Uniformizar para 3 tamanhos: título 0.82rem, valor 1.7rem (principal 2.1rem, duplo 1.35rem). | G14: Alta | H14: M | I14: Por fazer
A15: C11 | B15: Grelha da linha de KPIs | C15: Dois blocos de colunas Bootstrap com espaçadores de 26px para alinhar as etiquetas. | D15: .opt-section-box-summary (var(--bg-card), raio 10, padding 12) com uma .row g-2 de colunas .col iguais. | E15: Layout mais irregular. | F15: Agrupar cada linha de KPIs numa .opt-section-box-summary com colunas iguais; elimina os espaçadores. | G15: Média | H15: M | I15: Por fazer
... A25: C21 | B25: Tipografia | C25: Segoe UI, Tahoma… (igual). h2 do cabeçalho ~2rem. | D25: Segoe UI (igual). Escala: título app 1.3rem · secção 1rem · cartão 0.82rem · valor 1.7/2.1rem · tabela 0.8rem · rótulos 0.66–0.72rem. | E25: Fonte igual; escala diferente. | F25: Seguir a escala da folha "Tipografia". | G25: Média | H25: S | I25: Por fazer

Sheet Tipografia
A1: Escala tipográfica: painel atual vs statusOPT
A2: Tamanhos em rem (1rem ≈ 16px). Peso: 400 normal · 600 semi · 700 bold · 800 extra.
A4: Elemento | B4: Painel TE: tamanho | C4: Painel TE: peso / cor | D4: statusOPT: tamanho | E4: statusOPT: peso / cor | F4: Igual?
A5: Título da aplicação | B5: h2 (~2rem) | C5: 700 · text-dark | D5: 1.3rem | E5: 700 · var(--cyan-accent) · letter-spacing .5px | F5: =IF(B5=D5,"Sim","Não") -> Não
A6: Subtítulo / estado no cabeçalho | B6: small (0.875rem) | C6: 400 · muted | D6: 0.85rem | E6: 400 · var(--text-muted) em pílula | F6: =IF(B6=D6,"Sim","Não") -> Não
A7: Título de secção | B7: 1.05rem | C7: 700 · #1e293b (aberto #005a9e) | D7: 1rem | E7: 700 · var(--cyan-accent) | F7: =IF(B7=D7,"Sim","Não") -> Não
A8: Etiqueta de grupo | B8: 0.68–0.75rem | C8: 700 · #475569 em pílula | D8: 0.66rem | E8: 700 · maiúsculas · var(--text-muted) | F8: =IF(B8=D8,"Sim","Não") -> Não
A9: Título de KPI | B9: 0.6 / 0.65 / 0.72 / 0.8 / 0.85rem | C9: 700 · #64748b ou text-dark | D9: 0.82rem | E9: 700 · maiúsculas · var(--text-label) | F9: =IF(B9=D9,"Sim","Não") -> Não
A10: Valor de KPI principal | B10: 2.8rem / 2.2rem | C10: 800 · text-dark | D10: 2.1rem | E10: 800 · cor do semáforo | F10: =IF(B10=D10,"Sim","Não") -> Não
A11: Valor de KPI normal | B11: 1.8rem | C11: 700/800 · text-dark ou cor | D11: 1.7rem | E11: 800 · cor do semáforo ou var(--text-strong) | F11: =IF(B11=D11,"Sim","Não") -> Não
A12: Valor em cartão duplo | B12: 1.5rem | C12: 700 · text-dark | D12: 1.35rem | E12: 800 · var(--text-strong) | F12: =IF(B12=D12,"Sim","Não") -> Não
A13: Texto auxiliar de KPI ("N de M") | B13: 0.7rem | C13: 400 · muted | D13: 0.72rem | E13: 500 · var(--text-muted) | F13: =IF(B13=D13,"Sim","Não") -> Não
A14: Título de gráfico | B14: 1.02rem (0.88rem num) | C14: 700 · text-dark | D14: 0.9rem | E14: 700 · var(--text-strong) | F14: =IF(B14=D14,"Sim","Não") -> Não
A15: Dica "Clique para filtrar" | B15: 0.72rem | C15: 400 · muted | D15: 0.72rem | E15: 400 · var(--text-muted) | F15: =IF(B15=D15,"Sim","Não") -> Sim
A16: Botões pequenos (toggle) | B16: 0.72rem | C16: 400 · btn-xs | D16: 0.72rem | E16: 700 | F16: =IF(B16=D16,"Sim","Não") -> Sim
... A20: Rótulos de dados nos gráficos | B20: 11px | C20: bold · #1e293b | D20: 11px | E20: bold · corTema('--chart-text-strong') | F20: =IF(B20=D20,"Sim","Não") -> Sim

Sheet Plano de Ação
A1: Ordem recomendada de implementação
A2: Cada fase deixa o painel utilizável. As referências apontam para as linhas das outras folhas.
A4: Passo | B4: Fase | C4: O que fazer | D4: Referências | E4: Prioridade | F4: Esforço | G4: Estado
A5: 1 | B5: 1 · Base de tema | C5: Copiar :root (escuro) e :root[data-theme=light] do statusOPT; html/body com var(--sp-bg) e var(--text-main). | D5: Tokens statusOPT; C01 | E5: Alta | F5: S | G5: Por fazer
A6: 2 | B6: 1 · Base de tema | C6: Substituir todas as cores escritas à mão no CSS por variáveis. | D6: Cores Painel TE | E6: Alta | F6: M | G6: Por fazer
A7: 3 | B7: 1 · Base de tema | C7: Copiar os overrides Bootstrap (.btn-outline-*, .btn-*, .text-*, .dropdown-menu, .form-select). | D7: C05 | E7: Alta | F7: S | G7: Por fazer
A8: 4 | B8: 1 · Base de tema | C8: Interruptor sol/lua + aplicarTema() com a chave "opt_tema_v1". | D8: C02 | E8: Alta | F8: S | G8: Por fazer
A9: 5 | B9: 2 · Estrutura | C9: Cabeçalho .opt-header-bar + pílula "Atualizado a". | D9: C03, C04 | E9: Alta | F9: S | G9: Por fazer
A10: 6 | B10: 2 · Estrutura | C10: Acordeão, barra de filtros e etiquetas de grupo com o estilo statusOPT. | D10: C06–C09 | E10: Média | F10: M | G10: Por fazer
A11: 7 | B11: 3 · Indicadores | C11: Copiar getCumprimentoColor(), getCumprimentoBadgeClass(), getDelayCardConfig(); criar getPontualidadeComunicacaoColor() (R2). | D11: Regras de Cor R1–R3 | E11: Alta | F11: S | G11: Por fazer
A12: 8 | B12: 3 · Indicadores | C12: Reescrever updateKPIs()/updateComplianceKPIs(): deixam de mexer em background-color e border-left-color; passam a pintar só o número. | D12: K01, K04, K05, K08, K15 | E12: Alta | F12: S | G12: Por fazer
A13: 9 | B13: 3 · Indicadores | C13: Reconstruir os cartões em .opt-summary-card / .opt-kpi-dual (principal, duplos, neutros). | D13: K01–K15; C10, C11 | E13: Alta | F13: M | G13: Por fazer
A14: 10 | B14: 4 · Gráficos | C14: Função corTema(); eixos, grelha, legendas e rótulos com as variações de --chart-*; redesenhar ao trocar tema. | D14: Gráficos G01–G11 | E14: Alta | F14: M | G14: Por fazer
A15: 11 | B15: 4 · Gráficos | C15: Trocar as cores das séries (Área ciano, C.C. verde, paleta de 12 cores no donut). | D15: Gráficos | E15: Média | F15: S | G15: Por fazer
A16: 12 | B16: 4 · Gráficos | C16: Cartões de gráfico .opt-chart-card e toggles .opt-chart-toggle. | D16: C12, C13 | E16: Média | F16: S | G16: Por fazer
... A19: 15 | B19: Opcional (ambos) | C19: Variáveis --kpi-ok/--kpi-alerta/--kpi-critico com tons escuros no tema claro, nos dois ficheiros (contraste). | D19: Regras de Cor N1 | E19: Baixa | F19: S | G19: Por fazer
